Workbook
Name CT: Settings!$B$5
Name QMAX: Settings!$B$7
Name TOL: Settings!$B$8
Name WT: Settings!$B$6
Name YT: Settings!$B$4

Sheet Guide
A1: KRGI ACADEMIC AUDIT FRAMEWORK (NBA Tier-I aligned)
A2: Group: K. Ramakrishnan Group of Institutions - KRCT, KRCE, MKCE. Scope: every department of all three institutes.
A4: 1. Audit cycles
A5: Mid-Semester audit: cross-department WITHIN the same institute (e.g., KRCT ECE auditors audit KRCT CSE). Scope = metrics marked 'Yes' in the Mid-Sem column (mainly Plan/Do/Check process metrics).
A6: End-Semester audit: CROSS-INSTITUTIONAL (auditors from KRCT/KRCE/MKCE audit a different institute). Scope = all metrics, C1 to C9.
A7: Auditors are drawn from the pooled list on 'Auditor Pool' (two per department: one senior + one with 3-5 years' experience, nominated by Head-IQAC). The deployment rule is checked automatically on 'Audit Allocation' and on each 'Dept Audit' sheet.
A9: 2. Two-stage method
A10: Stage A - Digital audit: the department uploads proof for every metric to its Drive evidence folder and pastes the link in column P, fills the claimed value / self-score (column O) and evidence status (Q). Auditors do a desk review and enter the audited value / score (R).
A11: Stage B - Physical audit (one day): auditors visit the department to validate the claims. Column V flags 'Mandatory' checks (evidence not complete, or claim exceeds audited value by more than the tolerance in Settings). Other metrics are sampled. The validated value goes in X; the final score uses the physical result wherever it was Partially Verified / Not Verified.
A13: 3. Grading (thresholds editable on 'Settings')
A14: Y : more than 75% | C : 60% to 75% | W : 40% to below 60% | D : below 40%
A15: Grades are computed for every metric, sub-criterion, criterion and the overall department score.
... A32: Example (quantitative): 4.6 Placement, Benchmark 80, Claimed 72, Audited 68 -> Digital 85% (Y); physical audit finds offer letters for 60 -> Partially Verified, validated 60 -> Final 75% (C).

Sheet KRGI Dashboard
A1: KRGI ACADEMIC AUDIT DASHBOARD - ALL DEPARTMENTS (KRCT + KRCE + MKCE)
A2: Enter validated % per criterion from each department's 'Criterion Summary' (column G), or link with IMPORTRANGE. Grades and counts are automatic.
A4: Institute | B4: Cycle | C4: Departments audited | D4: Average overall % | E4: Grade
A5: KRCT | B5: Mid-Semester | C5: =COUNTIFS($A$14:$A$200,A5,$B$14:$B$200,B5,$M$14:$M$200,"<>") -> 0 | D5: =IF(C5=0,"",AVERAGEIFS($M$14:$M$200,$A$14:$A$200,A5,$B$14:$B$200,B5)) | E5: =IF(D5="","",IF(D5>YT,"Y",IF(D5>=CT,"C",IF(D5>=WT,"W","D"))))
A6: KRCT | B6: End-Semester | C6: =COUNTIFS($A$14:$A$200,A6,$B$14:$B$200,B6,$M$14:$M$200,"<>") -> 0 | D6: =IF(C6=0,"",AVERAGEIFS($M$14:$M$200,$A$14:$A$200,A6,$B$14:$B$200,B6)) | E6: =IF(D6="","",IF(D6>YT,"Y",IF(D6>=CT,"C",IF(D6>=WT,"W","D"))))
A7: KRCE | B7: Mid-Semester | C7: =COUNTIFS($A$14:$A$200,A7,$B$14:$B$200,B7,$M$14:$M$200,"<>") -> 0 | D7: =IF(C7=0,"",AVERAGEIFS($M$14:$M$200,$A$14:$A$200,A7,$B$14:$B$200,B7)) | E7: =IF(D7="","",IF(D7>YT,"Y",IF(D7>=CT,"C",IF(D7>=WT,"W","D"))))
A8: KRCE | B8: End-Semester | C8: =COUNTIFS($A$14:$A$200,A8,$B$14:$B$200,B8,$M$14:$M$200,"<>") -> 0 | D8: =IF(C8=0,"",AVERAGEIFS($M$14:$M$200,$A$14:$A$200,A8,$B$14:$B$200,B8)) | E8: =IF(D8="","",IF(D8>YT,"Y",IF(D8>=CT,"C",IF(D8>=WT,"W","D"))))
A9: MKCE | B9: Mid-Semester | C9: =COUNTIFS($A$14:$A$200,A9,$B$14:$B$200,B9,$M$14:$M$200,"<>") -> 0 | D9: =IF(C9=0,"",AVERAGEIFS($M$14:$M$200,$A$14:$A$200,A9,$B$14:$B$200,B9)) | E9: =IF(D9="","",IF(D9>YT,"Y",IF(D9>=CT,"C",IF(D9>=WT,"W","D"))))
A10: MKCE | B10: End-Semester | C10: =COUNTIFS($A$14:$A$200,A10,$B$14:$B$200,B10,$M$14:$M$200,"<>") -> 0 | D10: =IF(C10=0,"",AVERAGEIFS($M$14:$M$200,$A$14:$A$200,A10,$B$14:$B$200,B10)) | E10: =IF(D10="","",IF(D10>YT,"Y",IF(D10>=CT,"C",IF(D10>=WT,"W","D"))))
A13: Institute | B13: Department | C13: Cycle | D13: C1 | E13: C2 | F13: C3 | G13: C4 | H13: C5 | I13: C6 | J13: C7 | K13: C8 | L13: C9 | M13: Overall % | N13: Overall grade | O13: Criteria at Y | P13: Criteria at C | Q13: Criteria at W | R13: Criteria at D | S13: Audit status | T13: Link to department audit file
A14: KRCT | B14: AI&DS | C14: Mid-Semester | N14: =IF(M14="","",IF(M14>YT,"Y",IF(M14>=CT,"C",IF(M14>=WT,"W","D")))) | O14: =COUNTIF(D14:L14,">"&YT) -> 0 | P14: =COUNTIFS(D14:L14,">="&CT,D14:L14,"<="&YT) -> 0 | Q14: =COUNTIFS(D14:L14,">="&WT,D14:L14,"<"&CT) -> 0 | R14: =COUNTIF(D14:L14,"<"&WT) -> 0
A15: KRCT | B15: AI&ML | C15: Mid-Semester | N15: =IF(M15="","",IF(M15>YT,"Y",IF(M15>=CT,"C",IF(M15>=WT,"W","D")))) | O15: =COUNTIF(D15:L15,">"&YT) -> 0 | P15: =COUNTIFS(D15:L15,">="&CT,D15:L15,"<="&YT) -> 0 | Q15: =COUNTIFS(D15:L15,">="&WT,D15:L15,"<"&CT) -> 0 | R15: =COUNTIF(D15:L15,"<"&WT) -> 0
A16: KRCT | B16: IT | C16: Mid-Semester | N16: =IF(M16="","",IF(M16>YT,"Y",IF(M16>=CT,"C",IF(M16>=WT,"W","D")))) | O16: =COUNTIF(D16:L16,">"&YT) -> 0 | P16: =COUNTIFS(D16:L16,">="&CT,D16:L16,"<="&YT) -> 0 | Q16: =COUNTIFS(D16:L16,">="&WT,D16:L16,"<"&CT) -> 0 | R16: =COUNTIF(D16:L16,"<"&WT) -> 0
A17: KRCT | B17: CSE | C17: Mid-Semester | N17: =IF(M17="","",IF(M17>YT,"Y",IF(M17>=CT,"C",IF(M17>=WT,"W","D")))) | O17: =COUNTIF(D17:L17,">"&YT) -> 0 | P17: =COUNTIFS(D17:L17,">="&CT,D17:L17,"<="&YT) -> 0 | Q17: =COUNTIFS(D17:L17,">="&WT,D17:L17,"<"&CT) -> 0 | R17: =COUNTIF(D17:L17,"<"&WT) -> 0
A18: KRCT | B18: ECE | C18: Mid-Semester | N18: =IF(M18="","",IF(M18>YT,"Y",IF(M18>=CT,"C",IF(M18>=WT,"W","D")))) | O18: =COUNTIF(D18:L18,">"&YT) -> 0 | P18: =COUNTIFS(D18:L18,">="&CT,D18:L18,"<="&YT) -> 0 | Q18: =COUNTIFS(D18:L18,">="&WT,D18:L18,"<"&CT) -> 0 | R18: =COUNTIF(D18:L18,"<"&WT) -> 0
A19: KRCT | B19: EEE | C19: Mid-Semester | N19: =IF(M19="","",IF(M19>YT,"Y",IF(M19>=CT,"C",IF(M19>=WT,"W","D")))) | O19: =COUNTIF(D19:L19,">"&YT) -> 0 | P19: =COUNTIFS(D19:L19,">="&CT,D19:L19,"<="&YT) -> 0 | Q19: =COUNTIFS(D19:L19,">="&WT,D19:L19,"<"&CT) -> 0 | R19: =COUNTIF(D19:L19,"<"&WT) -> 0
A20: KRCT | B20: MECH | C20: Mid-Semester | N20: =IF(M20="","",IF(M20>YT,"Y",IF(M20>=CT,"C",IF(M20>=WT,"W","D")))) | O20: =COUNTIF(D20:L20,">"&YT) -> 0 | P20: =COUNTIFS(D20:L20,">="&CT,D20:L20,"<="&YT) -> 0 | Q20: =COUNTIFS(D20:L20,">="&WT,D20:L20,"<"&CT) -> 0 | R20: =COUNTIF(D20:L20,"<"&WT) -> 0
A21: KRCT | B21: CIVIL | C21: Mid-Semester | N21: =IF(M21="","",IF(M21>YT,"Y",IF(M21>=CT,"C",IF(M21>=WT,"W","D")))) | O21: =COUNTIF(D21:L21,">"&YT) -> 0 | P21: =COUNTIFS(D21:L21,">="&CT,D21:L21,"<="&YT) -> 0 | Q21: =COUNTIFS(D21:L21,">="&WT,D21:L21,"<"&CT) -> 0 | R21: =COUNTIF(D21:L21,"<"&WT) -> 0
A22: KRCT | B22: S&H | C22: Mid-Semester | N22: =IF(M22="","",IF(M22>YT,"Y",IF(M22>=CT,"C",IF(M22>=WT,"W","D")))) | O22: =COUNTIF(D22:L22,">"&YT) -> 0 | P22: =COUNTIFS(D22:L22,">="&CT,D22:L22,"<="&YT) -> 0 | Q22: =COUNTIFS(D22:L22,">="&WT,D22:L22,"<"&CT) -> 0 | R22: =COUNTIF(D22:L22,"<"&WT) -> 0
A23: KRCE | B23: AI&DS | C23: Mid-Semester | N23: =IF(M23="","",IF(M23>YT,"Y",IF(M23>=CT,"C",IF(M23>=WT,"W","D")))) | O23: =COUNTIF(D23:L23,">"&YT) -> 0 | P23: =COUNTIFS(D23:L23,">="&CT,D23:L23,"<="&YT) -> 0 | Q23: =COUNTIFS(D23:L23,">="&WT,D23:L23,"<"&CT) -> 0 | R23: =COUNTIF(D23:L23,"<"&WT) -> 0
A24: KRCE | B24: AI&ML | C24: Mid-Semester | N24: =IF(M24="","",IF(M24>YT,"Y",IF(M24>=CT,"C",IF(M24>=WT,"W","D")))) | O24: =COUNTIF(D24:L24,">"&YT) -> 0 | P24: =COUNTIFS(D24:L24,">="&CT,D24:L24,"<="&YT) -> 0 | Q24: =COUNTIFS(D24:L24,">="&WT,D24:L24,"<"&CT) -> 0 | R24: =COUNTIF(D24:L24,"<"&WT) -> 0
A25: KRCE | B25: IT | C25: Mid-Semester | N25: =IF(M25="","",IF(M25>YT,"Y",IF(M25>=CT,"C",IF(M25>=WT,"W","D")))) | O25: =COUNTIF(D25:L25,">"&YT) -> 0 | P25: =COUNTIFS(D25:L25,">="&CT,D25:L25,"<="&YT) -> 0 | Q25: =COUNTIFS(D25:L25,">="&WT,D25:L25,"<"&CT) -> 0 | R25: =COUNTIF(D25:L25,"<"&WT) -> 0
... A73: MKCE | B73: CSE (CS) | C73: End-Semester | N73: =IF(M73="","",IF(M73>YT,"Y",IF(M73>=CT,"C",IF(M73>=WT,"W","D")))) | O73: =COUNTIF(D73:L73,">"&YT) -> 0 | P73: =COUNTIFS(D73:L73,">="&CT,D73:L73,"<="&YT) -> 0 | Q73: =COUNTIFS(D73:L73,">="&WT,D73:L73,"<"&CT) -> 0 | R73: =COUNTIF(D73:L73,"<"&WT) -> 0

Sheet All Criteria
A1: ALL CRITERIA C1-C9 - QUANTITATIVE METRICS (1000 marks)
A2: Combined view: values come automatically from the C1-C9 Validation Rubrics and Quantitative tabs. Enter Benchmark, Validated value, Items checked, Valid items and Auditor remarks in the Cn Validation Rubrics tabs.
A4: Code | B4: Metric | C4: How to measure | D4: Unit | E4: Max marks | F4: Benchmark | G4: Validated value | H4: Marks obtained | I4: Percentage | J4: Grade | K4: Y | L4: C | M4: W | N4: D | O4: Items checked | P4: Valid items | Q4: Sample validity % | R4: Auditor remarks
A5: C1 | B5: CRITERION 1 - OUTCOME-BASED CURRICULUM
A6: 1.1 | B6: Vision, Mission and PEOs | E6: #REF! | F6: #REF! | G6: #REF! | H6: =IF(COUNT(H7:H14)=0,"",SUM(H7:H14)) | I6: =IF(H6="","",ROUND(H6/E6*100,2)) | J6: =IF(I6="","",IF(I6>YT*100,"Y",IF(I6>=CT*100,"C",IF(I6>=WT*100,"W","D")))) | K6: =SUM(K7:K14) -> #VALUE! | L6: =SUM(L7:L14) -> #VALUE! | M6: =SUM(M7:M14) -> #VALUE! | N6: =SUM(N7:N14) -> #VALUE! | O6: =IF(COUNT(O7:O14)=0,"",SUM(O7:O14)) | P6: =IF(COUNT(P7:P14)=0,"",SUM(P7:P14)) | Q6: =IF(N(O6)=0,"",ROUND(N(P6)/O6*100,2))
A7: 1.1.a | B7: Approval of Vision & Mission (1.1.1) | C7: Approvals obtained (IQAC, DAB, GB) / Approvals required | D7: % | E7: #REF! | F7: #REF! | G7: #REF! | H7: =IF(OR(G7="",F7="",F7=0),"",ROUND(E7*MIN(G7/F7,1),2)) -> #VALUE! | I7: =IF(H7="","",ROUND(H7/E7*100,2)) -> #VALUE! | J7: =IF(I7="","",IF(I7>YT*100,"Y",IF(I7>=CT*100,"C",IF(I7>=WT*100,"W","D")))) -> #VALUE! | K7: =IF($J7="Y",1,"") -> #VALUE! | L7: =IF($J7="C",1,"") -> #VALUE! | M7: =IF($J7="W",1,"") -> #VALUE! | N7: =IF($J7="D",1,"") -> #VALUE! | O7: =IF('C1 Validation Rubrics'!M9="","",'C1 Validation Rubrics'!M9) | P7: =IF('C1 Validation Rubrics'!N9="","",'C1 Validation Rubrics'!N9) | Q7: =IF(N(O7)=0,"",ROUND(N(P7)/O7*100,2)) | R7: =IF('C1 Validation Rubrics'!O9="","",'C1 Validation Rubrics'!O9)
A8: 1.1.b | B8: Quality of PEOs (1.1.2) | C8: PEOs meeting criteria (specific, measurable, 3-5 yrs after graduation) / PEOs defined | D8: % | E8: #REF! | F8: #REF! | G8: #REF! | H8: =IF(OR(G8="",F8="",F8=0),"",ROUND(E8*MIN(G8/F8,1),2)) -> #VALUE! | I8: =IF(H8="","",ROUND(H8/E8*100,2)) -> #VALUE! | J8: =IF(I8="","",IF(I8>YT*100,"Y",IF(I8>=CT*100,"C",IF(I8>=WT*100,"W","D")))) -> #VALUE! | K8: =IF($J8="Y",1,"") -> #VALUE! | L8: =IF($J8="C",1,"") -> #VALUE! | M8: =IF($J8="W",1,"") -> #VALUE! | N8: =IF($J8="D",1,"") -> #VALUE! | O8: =IF('C1 Validation Rubrics'!M10="","",'C1 Validation Rubrics'!M10) | P8: =IF('C1 Validation Rubrics'!N10="","",'C1 Validation Rubrics'!N10) | Q8: =IF(N(O8)=0,"",ROUND(N(P8)/O8*100,2)) | R8: =IF('C1 Validation Rubrics'!O10="","",'C1 Validation Rubrics'!O10)
A9: 1.1.c | B9: Stakeholder categories consulted (1.1.3) | C9: Categories consulted (students, alumni, employers, parents, faculty, industry) / 6 | D9: % | E9: #REF! | F9: #REF! | G9: #REF! | H9: =IF(OR(G9="",F9="",F9=0),"",ROUND(E9*MIN(G9/F9,1),2)) -> #VALUE! | I9: =IF(H9="","",ROUND(H9/E9*100,2)) -> #VALUE! | J9: =IF(I9="","",IF(I9>YT*100,"Y",IF(I9>=CT*100,"C",IF(I9>=WT*100,"W","D")))) -> #VALUE! | K9: =IF($J9="Y",1,"") -> #VALUE! | L9: =IF($J9="C",1,"") -> #VALUE! | M9: =IF($J9="W",1,"") -> #VALUE! | N9: =IF($J9="D",1,"") -> #VALUE! | O9: =IF('C1 Validation Rubrics'!M11="","",'C1 Validation Rubrics'!M11) | P9: =IF('C1 Validation Rubrics'!N11="","",'C1 Validation Rubrics'!N11) | Q9: =IF(N(O9)=0,"",ROUND(N(P9)/O9*100,2)) | R9: =IF('C1 Validation Rubrics'!O11="","",'C1 Validation Rubrics'!O11)
A10: 1.1.d | B10: Stakeholder survey responses (1.1.3) | C10: Survey responses received / Target responses | D10: % | E10: #REF! | F10: #REF! | G10: #REF! | H10: =IF(OR(G10="",F10="",F10=0),"",ROUND(E10*MIN(G10/F10,1),2)) -> #VALUE! | I10: =IF(H10="","",ROUND(H10/E10*100,2)) -> #VALUE! | J10: =IF(I10="","",IF(I10>YT*100,"Y",IF(I10>=CT*100,"C",IF(I10>=WT*100,"W","D")))) -> #VALUE! | K10: =IF($J10="Y",1,"") -> #VALUE! | L10: =IF($J10="C",1,"") -> #VALUE! | M10: =IF($J10="W",1,"") -> #VALUE! | N10: =IF($J10="D",1,"") -> #VALUE! | O10: =IF('C1 Validation Rubrics'!M12="","",'C1 Validation Rubrics'!M12) | P10: =IF('C1 Validation Rubrics'!N12="","",'C1 Validation Rubrics'!N12) | Q10: =IF(N(O10)=0,"",ROUND(N(P10)/O10*100,2)) | R10: =IF('C1 Validation Rubrics'!O12="","",'C1 Validation Rubrics'!O12)
A11: 1.1.e | B11: Dissemination points (1.1.4) | C11: Places displayed (website, dept, labs, classrooms, course files, handbook) / Required places | D11: % | E11: #REF! | F11: #REF! | G11: #REF! | H11: =IF(OR(G11="",F11="",F11=0),"",ROUND(E11*MIN(G11/F11,1),2)) -> #VALUE! | I11: =IF(H11="","",ROUND(H11/E11*100,2)) -> #VALUE! | J11: =IF(I11="","",IF(I11>YT*100,"Y",IF(I11>=CT*100,"C",IF(I11>=WT*100,"W","D")))) -> #VALUE! | K11: =IF($J11="Y",1,"") -> #VALUE! | L11: =IF($J11="C",1,"") -> #VALUE! | M11: =IF($J11="W",1,"") -> #VALUE! | N11: =IF($J11="D",1,"") -> #VALUE! | O11: =IF('C1 Validation Rubrics'!M13="","",'C1 Validation Rubrics'!M13) | P11: =IF('C1 Validation Rubrics'!N13="","",'C1 Validation Rubrics'!N13) | Q11: =IF(N(O11)=0,"",ROUND(N(P11)/O11*100,2)) | R11: =IF('C1 Validation Rubrics'!O13="","",'C1 Validation Rubrics'!O13)
A12: 1.1.f | B12: Stakeholder awareness (1.1.4) | C12: Sampled students able to state V/M/PEOs / Students sampled | D12: % | E12: #REF! | F12: #REF! | G12: #REF! | H12: =IF(OR(G12="",F12="",F12=0),"",ROUND(E12*MIN(G12/F12,1),2)) -> #VALUE! | I12: =IF(H12="","",ROUND(H12/E12*100,2)) -> #VALUE! | J12: =IF(I12="","",IF(I12>YT*100,"Y",IF(I12>=CT*100,"C",IF(I12>=WT*100,"W","D")))) -> #VALUE! | K12: =IF($J12="Y",1,"") -> #VALUE! | L12: =IF($J12="C",1,"") -> #VALUE! | M12: =IF($J12="W",1,"") -> #VALUE! | N12: =IF($J12="D",1,"") -> #VALUE! | O12: =IF('C1 Validation Rubrics'!M14="","",'C1 Validation Rubrics'!M14) | P12: =IF('C1 Validation Rubrics'!N14="","",'C1 Validation Rubrics'!N14) | Q12: =IF(N(O12)=0,"",ROUND(N(P12)/O12*100,2)) | R12: =IF('C1 Validation Rubrics'!O14="","",'C1 Validation Rubrics'!O14)
A13: 1.1.g | B13: PEO-Mission mapping completeness (1.1.5) | C13: Mapping cells filled with justification / Total mapping cells | D13: % | E13: #REF! | F13: #REF! | G13: #REF! | H13: =IF(OR(G13="",F13="",F13=0),"",ROUND(E13*MIN(G13/F13,1),2)) -> #VALUE! | I13: =IF(H13="","",ROUND(H13/E13*100,2)) -> #VALUE! | J13: =IF(I13="","",IF(I13>YT*100,"Y",IF(I13>=CT*100,"C",IF(I13>=WT*100,"W","D")))) -> #VALUE! | K13: =IF($J13="Y",1,"") -> #VALUE! | L13: =IF($J13="C",1,"") -> #VALUE! | M13: =IF($J13="W",1,"") -> #VALUE! | N13: =IF($J13="D",1,"") -> #VALUE! | O13: =IF('C1 Validation Rubrics'!M15="","",'C1 Validation Rubrics'!M15) | P13: =IF('C1 Validation Rubrics'!N15="","",'C1 Validation Rubrics'!N15) | Q13: =IF(N(O13)=0,"",ROUND(N(P13)/O13*100,2)) | R13: =IF('C1 Validation Rubrics'!O15="","",'C1 Validation Rubrics'!O15)
A14: 1.1.h | B14: PEO-Mission correlation strength (1.1.5) | C14: PEOs with strong (3) correlation to at least one mission element / PEOs defined | D14: % | E14: #REF! | F14: #REF! | G14: #REF! | H14: =IF(OR(G14="",F14="",F14=0),"",ROUND(E14*MIN(G14/F14,1),2)) -> #VALUE! | I14: =IF(H14="","",ROUND(H14/E14*100,2)) -> #VALUE! | J14: =IF(I14="","",IF(I14>YT*100,"Y",IF(I14>=CT*100,"C",IF(I14>=WT*100,"W","D")))) -> #VALUE! | K14: =IF($J14="Y",1,"") -> #VALUE! | L14: =IF($J14="C",1,"") -> #VALUE! | M14: =IF($J14="W",1,"") -> #VALUE! | N14: =IF($J14="D",1,"") -> #VALUE! | O14: =IF('C1 Validation Rubrics'!M16="","",'C1 Validation Rubrics'!M16) | P14: =IF('C1 Validation Rubrics'!N16="","",'C1 Validation Rubrics'!N16) | Q14: =IF(N(O14)=0,"",ROUND(N(P14)/O14*100,2)) | R14: =IF('C1 Validation Rubrics'!O16="","",'C1 Validation Rubrics'!O16)
A15: 1.2 | B15: Curriculum structure and features | E15: #REF! | F15: #REF! | G15: #REF! | H15: =IF(COUNT(H16:H22)=0,"",SUM(H16:H22)) | I15: =IF(H15="","",ROUND(H15/E15*100,2)) | J15: =IF(I15="","",IF(I15>YT*100,"Y",IF(I15>=CT*100,"C",IF(I15>=WT*100,"W","D")))) | K15: =SUM(K16:K22) -> #VALUE! | L15: =SUM(L16:L22) -> #VALUE! | M15: =SUM(M16:M22) -> #VALUE! | N15: =SUM(N16:N22) -> #VALUE! | O15: =IF(COUNT(O16:O22)=0,"",SUM(O16:O22)) | P15: =IF(COUNT(P16:P22)=0,"",SUM(P16:P22)) | Q15: =IF(N(O15)=0,"",ROUND(N(P15)/O15*100,2))
A16: 1.2.a | B16: Curriculum feedback collected and analysed (1.2.1) | C16: Stakeholder categories with feedback analysed / 4 (students, alumni, employers, faculty) | D16: % | E16: #REF! | F16: #REF! | G16: #REF! | H16: =IF(OR(G16="",F16="",F16=0),"",ROUND(E16*MIN(G16/F16,1),2)) -> #VALUE! | I16: =IF(H16="","",ROUND(H16/E16*100,2)) -> #VALUE! | J16: =IF(I16="","",IF(I16>YT*100,"Y",IF(I16>=CT*100,"C",IF(I16>=WT*100,"W","D")))) -> #VALUE! | K16: =IF($J16="Y",1,"") -> #VALUE! | L16: =IF($J16="C",1,"") -> #VALUE! | M16: =IF($J16="W",1,"") -> #VALUE! | N16: =IF($J16="D",1,"") -> #VALUE! | O16: =IF('C1 Validation Rubrics'!M18="","",'C1 Validation Rubrics'!M18) | P16: =IF('C1 Validation Rubrics'!N18="","",'C1 Validation Rubrics'!N18) | Q16: =IF(N(O16)=0,"",ROUND(N(P16)/O16*100,2)) | R16: =IF('C1 Validation Rubrics'!O18="","",'C1 Validation Rubrics'!O18)
A17: 1.2.b | B17: Curriculum gaps addressed (1.2.1) | C17: Gaps closed through BoS revision or content beyond syllabus / Gaps identified | D17: % | E17: #REF! | F17: #REF! | G17: #REF! | H17: =IF(OR(G17="",F17="",F17=0),"",ROUND(E17*MIN(G17/F17,1),2)) -> #VALUE! | I17: =IF(H17="","",ROUND(H17/E17*100,2)) -> #VALUE! | J17: =IF(I17="","",IF(I17>YT*100,"Y",IF(I17>=CT*100,"C",IF(I17>=WT*100,"W","D")))) -> #VALUE! | K17: =IF($J17="Y",1,"") -> #VALUE! | L17: =IF($J17="C",1,"") -> #VALUE! | M17: =IF($J17="W",1,"") -> #VALUE! | N17: =IF($J17="D",1,"") -> #VALUE! | O17: =IF('C1 Validation Rubrics'!M19="","",'C1 Validation Rubrics'!M19) | P17: =IF('C1 Validation Rubrics'!N19="","",'C1 Validation Rubrics'!N19) | Q17: =IF(N(O17)=0,"",ROUND(N(P17)/O17*100,2)) | R17: =IF('C1 Validation Rubrics'!O19="","",'C1 Validation Rubrics'!O19)
A18: 1.2.c | B18: Complete syllabi (1.2.2) | C18: Courses with complete syllabus (COs, content, hours, references) / Courses in curriculum | D18: % | E18: #REF! | F18: #REF! | G18: #REF! | H18: =IF(OR(G18="",F18="",F18=0),"",ROUND(E18*MIN(G18/F18,1),2)) -> #VALUE! | I18: =IF(H18="","",ROUND(H18/E18*100,2)) -> #VALUE! | J18: =IF(I18="","",IF(I18>YT*100,"Y",IF(I18>=CT*100,"C",IF(I18>=WT*100,"W","D")))) -> #VALUE! | K18: =IF($J18="Y",1,"") -> #VALUE! | L18: =IF($J18="C",1,"") -> #VALUE! | M18: =IF($J18="W",1,"") -> #VALUE! | N18: =IF($J18="D",1,"") -> #VALUE! | O18: =IF('C1 Validation Rubrics'!M20="","",'C1 Validation Rubrics'!M20) | P18: =IF('C1 Validation Rubrics'!N20="","",'C1 Validation Rubrics'!N20) | Q18: =IF(N(O18)=0,"",ROUND(N(P18)/O18*100,2)) | R18: =IF('C1 Validation Rubrics'!O20="","",'C1 Validation Rubrics'!O20)
A19: 1.2.d | B19: Credit compliance (1.2.2) | C19: Semesters with credits within university/AICTE norms / Total semesters | D19: % | E19: #REF! | F19: #REF! | G19: #REF! | H19: =IF(OR(G19="",F19="",F19=0),"",ROUND(E19*MIN(G19/F19,1),2)) -> #VALUE! | I19: =IF(H19="","",ROUND(H19/E19*100,2)) -> #VALUE! | J19: =IF(I19="","",IF(I19>YT*100,"Y",IF(I19>=CT*100,"C",IF(I19>=WT*100,"W","D")))) -> #VALUE! | K19: =IF($J19="Y",1,"") -> #VALUE! | L19: =IF($J19="C",1,"") -> #VALUE! | M19: =IF($J19="W",1,"") -> #VALUE! | N19: =IF($J19="D",1,"") -> #VALUE! | O19: =IF('C1 Validation Rubrics'!M21="","",'C1 Validation Rubrics'!M21) | P19: =IF('C1 Validation Rubrics'!N21="","",'C1 Validation Rubrics'!N21) | Q19: =IF(N(O19)=0,"",ROUND(N(P19)/O19*100,2)) | R19: =IF('C1 Validation Rubrics'!O21="","",'C1 Validation Rubrics'!O21)
A20: 1.2.e | B20: Curriculum components within AICTE range (1.2.3) | C20: Categories within range (BS, ES, HSS, PC, PE, OE, Project) / 7 | D20: % | E20: #REF! | F20: #REF! | G20: #REF! | H20: =IF(OR(G20="",F20="",F20=0),"",ROUND(E20*MIN(G20/F20,1),2)) -> #VALUE! | I20: =IF(H20="","",ROUND(H20/E20*100,2)) -> #VALUE! | J20: =IF(I20="","",IF(I20>YT*100,"Y",IF(I20>=CT*100,"C",IF(I20>=WT*100,"W","D")))) -> #VALUE! | K20: =IF($J20="Y",1,"") -> #VALUE! | L20: =IF($J20="C",1,"") -> #VALUE! | M20: =IF($J20="W",1,"") -> #VALUE! | N20: =IF($J20="D",1,"") -> #VALUE! | O20: =IF('C1 Validation Rubrics'!M22="","",'C1 Validation Rubrics'!M22) | P20: =IF('C1 Validation Rubrics'!N22="","",'C1 Validation Rubrics'!N22) | Q20: =IF(N(O20)=0,"",ROUND(N(P20)/O20*100,2)) | R20: =IF('C1 Validation Rubrics'!O22="","",'C1 Validation Rubrics'!O22)
A21: 1.2.f | B21: Interdisciplinary / honours / minor options (1.2.4) | C21: Number of options offered | D21: No. | E21: #REF! | F21: #REF! | G21: #REF! | H21: =IF(OR(G21="",F21="",F21=0),"",ROUND(E21*MIN(G21/F21,1),2)) -> #VALUE! | I21: =IF(H21="","",ROUND(H21/E21*100,2)) -> #VALUE! | J21: =IF(I21="","",IF(I21>YT*100,"Y",IF(I21>=CT*100,"C",IF(I21>=WT*100,"W","D")))) -> #VALUE! | K21: =IF($J21="Y",1,"") -> #VALUE! | L21: =IF($J21="C",1,"") -> #VALUE! | M21: =IF($J21="W",1,"") -> #VALUE! | N21: =IF($J21="D",1,"") -> #VALUE! | O21: =IF('C1 Validation Rubrics'!M23="","",'C1 Validation Rubrics'!M23) | P21: =IF('C1 Validation Rubrics'!N23="","",'C1 Validation Rubrics'!N23) | Q21: =IF(N(O21)=0,"",ROUND(N(P21)/O21*100,2)) | R21: =IF('C1 Validation Rubrics'!O23="","",'C1 Validation Rubrics'!O23)
A22: 1.2.g | B22: Academic Bank of Credits registration (1.2.4) | C22: Students with ABC ID / Students on roll | D22: % | E22: #REF! | F22: #REF! | G22: #REF! | H22: =IF(OR(G22="",F22="",F22=0),"",ROUND(E22*MIN(G22/F22,1),2)) -> #VALUE! | I22: =IF(H22="","",ROUND(H22/E22*100,2)) -> #VALUE! | J22: =IF(I22="","",IF(I22>YT*100,"Y",IF(I22>=CT*100,"C",IF(I22>=WT*100,"W","D")))) -> #VALUE! | K22: =IF($J22="Y",1,"") -> #VALUE! | L22: =IF($J22="C",1,"") -> #VALUE! | M22: =IF($J22="W",1,"") -> #VALUE! | N22: =IF($J22="D",1,"") -> #VALUE! | O22: =IF('C1 Validation Rubrics'!M24="","",'C1 Validation Rubrics'!M24) | P22: =IF('C1 Validation Rubrics'!N24="","",'C1 Validation Rubrics'!N24) | Q22: =IF(N(O22)=0,"",ROUND(N(P22)/O22*100,2)) | R22: =IF('C1 Validation Rubrics'!O24="","",'C1 Validation Rubrics'!O24)
A23: 1.3 | B23: Mapping of POs and PSOs | E23: #REF! | F23: #REF! | G23: #REF! | H23: =IF(COUNT(H24:H26)=0,"",SUM(H24:H26)) | I23: =IF(H23="","",ROUND(H23/E23*100,2)) | J23: =IF(I23="","",IF(I23>YT*100,"Y",IF(I23>=CT*100,"C",IF(I23>=WT*100,"W","D")))) | K23: =SUM(K24:K26) -> #VALUE! | L23: =SUM(L24:L26) -> #VALUE! | M23: =SUM(M24:M26) -> #VALUE! | N23: =SUM(N24:N26) -> #VALUE! | O23: =IF(COUNT(O24:O26)=0,"",SUM(O24:O26)) | P23: =IF(COUNT(P24:P26)=0,"",SUM(P24:P26)) | Q23: =IF(N(O23)=0,"",ROUND(N(P23)/O23*100,2))
A24: 1.3.a | B24: PSOs defined and approved (1.3.1) | C24: PSOs approved by BoS/DAB / PSOs defined | D24: % | E24: #REF! | F24: #REF! | G24: #REF! | H24: =IF(OR(G24="",F24="",F24=0),"",ROUND(E24*MIN(G24/F24,1),2)) -> #VALUE! | I24: =IF(H24="","",ROUND(H24/E24*100,2)) -> #VALUE! | J24: =IF(I24="","",IF(I24>YT*100,"Y",IF(I24>=CT*100,"C",IF(I24>=WT*100,"W","D")))) -> #VALUE! | K24: =IF($J24="Y",1,"") -> #VALUE! | L24: =IF($J24="C",1,"") -> #VALUE! | M24: =IF($J24="W",1,"") -> #VALUE! | N24: =IF($J24="D",1,"") -> #VALUE! | O24: =IF('C1 Validation Rubrics'!M26="","",'C1 Validation Rubrics'!M26) | P24: =IF('C1 Validation Rubrics'!N26="","",'C1 Validation Rubrics'!N26) | Q24: =IF(N(O24)=0,"",ROUND(N(P24)/O24*100,2)) | R24: =IF('C1 Validation Rubrics'!O26="","",'C1 Validation Rubrics'!O26)
A25: 1.3.b | B25: Courses mapped to POs/PSOs (1.3.2) | C25: Courses with PO/PSO mapping / Courses in curriculum | D25: % | E25: #REF! | F25: #REF! | G25: #REF! | H25: =IF(OR(G25="",F25="",F25=0),"",ROUND(E25*MIN(G25/F25,1),2)) -> #VALUE! | I25: =IF(H25="","",ROUND(H25/E25*100,2)) -> #VALUE! | J25: =IF(I25="","",IF(I25>YT*100,"Y",IF(I25>=CT*100,"C",IF(I25>=WT*100,"W","D")))) -> #VALUE! | K25: =IF($J25="Y",1,"") -> #VALUE! | L25: =IF($J25="C",1,"") -> #VALUE! | M25: =IF($J25="W",1,"") -> #VALUE! | N25: =IF($J25="D",1,"") -> #VALUE! | O25: =IF('C1 Validation Rubrics'!M27="","",'C1 Validation Rubrics'!M27) | P25: =IF('C1 Validation Rubrics'!N27="","",'C1 Validation Rubrics'!N27) | Q25: =IF(N(O25)=0,"",ROUND(N(P25)/O25*100,2)) | R25: =IF('C1 Validation Rubrics'!O27="","",'C1 Validation Rubrics'!O27)
A26: 1.3.c | B26: Justified mappings (1.3.2) | C26: Mapped courses with written justification / Mapped courses | D26: % | E26: #REF! | F26: #REF! | G26: #REF! | H26: =IF(OR(G26="",F26="",F26=0),"",ROUND(E26*MIN(G26/F26,1),2)) -> #VALUE! | I26: =IF(H26="","",ROUND(H26/E26*100,2)) -> #VALUE! | J26: =IF(I26="","",IF(I26>YT*100,"Y",IF(I26>=CT*100,"C",IF(I26>=WT*100,"W","D")))) -> #VALUE! | K26: =IF($J26="Y",1,"") -> #VALUE! | L26: =IF($J26="C",1,"") -> #VALUE! | M26: =IF($J26="W",1,"") -> #VALUE! | N26: =IF($J26="D",1,"") -> #VALUE! | O26: =IF('C1 Validation Rubrics'!M28="","",'C1 Validation Rubrics'!M28) | P26: =IF('C1 Validation Rubrics'!N28="","",'C1 Validation Rubrics'!N28) | Q26: =IF(N(O26)=0,"",ROUND(N(P26)/O26*100,2)) | R26: =IF('C1 Validation Rubrics'!O28="","",'C1 Validation Rubrics'!O28)
A27: 1.4 | B27: Course Outcomes and Course Articulation Matrix | E27: #REF! | F27: #REF! | G27: #REF! | H27: =IF(COUNT(H28:H32)=0,"",SUM(H28:H32)) | I27: =IF(H27="","",ROUND(H27/E27*100,2)) | J27: =IF(I27="","",IF(I27>YT*100,"Y",IF(I27>=CT*100,"C",IF(I27>=WT*100,"W","D")))) | K27: =SUM(K28:K32) -> #VALUE! | L27: =SUM(L28:L32) -> #VALUE! | M27: =SUM(M28:M32) -> #VALUE! | N27: =SUM(N28:N32) -> #VALUE! | O27: =IF(COUNT(O28:O32)=0,"",SUM(O28:O32)) | P27: =IF(COUNT(P28:P32)=0,"",SUM(P28:P32)) | Q27: =IF(N(O27)=0,"",ROUND(N(P27)/O27*100,2))
A28: 1.4.a | B28: Courses with COs defined (1.4.1) | C28: Courses with COs / Courses offered | D28: % | E28: #REF! | F28: #REF! | G28: #REF! | H28: =IF(OR(G28="",F28="",F28=0),"",ROUND(E28*MIN(G28/F28,1),2)) -> #VALUE! | I28: =IF(H28="","",ROUND(H28/E28*100,2)) -> #VALUE! | J28: =IF(I28="","",IF(I28>YT*100,"Y",IF(I28>=CT*100,"C",IF(I28>=WT*100,"W","D")))) -> #VALUE! | K28: =IF($J28="Y",1,"") -> #VALUE! | L28: =IF($J28="C",1,"") -> #VALUE! | M28: =IF($J28="W",1,"") -> #VALUE! | N28: =IF($J28="D",1,"") -> #VALUE! | O28: =IF('C1 Validation Rubrics'!M30="","",'C1 Validation Rubrics'!M30) | P28: =IF('C1 Validation Rubrics'!N30="","",'C1 Validation Rubrics'!N30) | Q28: =IF(N(O28)=0,"",ROUND(N(P28)/O28*100,2)) | R28: =IF('C1 Validation Rubrics'!O30="","",'C1 Validation Rubrics'!O30)
A29: 1.4.b | B29: Measurable COs (1.4.1) | C29: COs with action verb and Bloom's level / Total COs | D29: % | E29: #REF! | F29: #REF! | G29: #REF! | H29: =IF(OR(G29="",F29="",F29=0),"",ROUND(E29*MIN(G29/F29,1),2)) -> #VALUE! | I29: =IF(H29="","",ROUND(H29/E29*100,2)) -> #VALUE! | J29: =IF(I29="","",IF(I29>YT*100,"Y",IF(I29>=CT*100,"C",IF(I29>=WT*100,"W","D")))) -> #VALUE! | K29: =IF($J29="Y",1,"") -> #VALUE! | L29: =IF($J29="C",1,"") -> #VALUE! | M29: =IF($J29="W",1,"") -> #VALUE! | N29: =IF($J29="D",1,"") -> #VALUE! | O29: =IF('C1 Validation Rubrics'!M31="","",'C1 Validation Rubrics'!M31) | P29: =IF('C1 Validation Rubrics'!N31="","",'C1 Validation Rubrics'!N31) | Q29: =IF(N(O29)=0,"",ROUND(N(P29)/O29*100,2)) | R29: =IF('C1 Validation Rubrics'!O31="","",'C1 Validation Rubrics'!O31)
A30: 1.4.c | B30: Higher-order COs (1.4.1) | C30: Courses with at least one CO at Apply level or above / Courses offered | D30: % | E30: #REF! | F30: #REF! | G30: #REF! | H30: =IF(OR(G30="",F30="",F30=0),"",ROUND(E30*MIN(G30/F30,1),2)) -> #VALUE! | I30: =IF(H30="","",ROUND(H30/E30*100,2)) -> #VALUE! | J30: =IF(I30="","",IF(I30>YT*100,"Y",IF(I30>=CT*100,"C",IF(I30>=WT*100,"W","D")))) -> #VALUE! | K30: =IF($J30="Y",1,"") -> #VALUE! | L30: =IF($J30="C",1,"") -> #VALUE! | M30: =IF($J30="W",1,"") -> #VALUE! | N30: =IF($J30="D",1,"") -> #VALUE! | O30: =IF('C1 Validation Rubrics'!M32="","",'C1 Validation Rubrics'!M32) | P30: =IF('C1 Validation Rubrics'!N32="","",'C1 Validation Rubrics'!N32) | Q30: =IF(N(O30)=0,"",ROUND(N(P30)/O30*100,2)) | R30: =IF('C1 Validation Rubrics'!O32="","",'C1 Validation Rubrics'!O32)
A31: 1.4.d | B31: Course Articulation Matrix prepared (1.4.2) | C31: Courses with CAM / Courses offered | D31: % | E31: #REF! | F31: #REF! | G31: #REF! | H31: =IF(OR(G31="",F31="",F31=0),"",ROUND(E31*MIN(G31/F31,1),2)) -> #VALUE! | I31: =IF(H31="","",ROUND(H31/E31*100,2)) -> #VALUE! | J31: =IF(I31="","",IF(I31>YT*100,"Y",IF(I31>=CT*100,"C",IF(I31>=WT*100,"W","D")))) -> #VALUE! | K31: =IF($J31="Y",1,"") -> #VALUE! | L31: =IF($J31="C",1,"") -> #VALUE! | M31: =IF($J31="W",1,"") -> #VALUE! | N31: =IF($J31="D",1,"") -> #VALUE! | O31: =IF('C1 Validation Rubrics'!M33="","",'C1 Validation Rubrics'!M33) | P31: =IF('C1 Validation Rubrics'!N33="","",'C1 Validation Rubrics'!N33) | Q31: =IF(N(O31)=0,"",ROUND(N(P31)/O31*100,2)) | R31: =IF('C1 Validation Rubrics'!O33="","",'C1 Validation Rubrics'!O33)
A32: 1.4.e | B32: CAM correlations justified (1.4.2) | C32: CAMs with justification for each correlation / CAMs prepared | D32: % | E32: #REF! | F32: #REF! | G32: #REF! | H32: =IF(OR(G32="",F32="",F32=0),"",ROUND(E32*MIN(G32/F32,1),2)) -> #VALUE! | I32: =IF(H32="","",ROUND(H32/E32*100,2)) -> #VALUE! | J32: =IF(I32="","",IF(I32>YT*100,"Y",IF(I32>=CT*100,"C",IF(I32>=WT*100,"W","D")))) -> #VALUE! | K32: =IF($J32="Y",1,"") -> #VALUE! | L32: =IF($J32="C",1,"") -> #VALUE! | M32: =IF($J32="W",1,"") -> #VALUE! | N32: =IF($J32="D",1,"") -> #VALUE! | O32: =IF('C1 Validation Rubrics'!M34="","",'C1 Validation Rubrics'!M34) | P32: =IF('C1 Validation Rubrics'!N34="","",'C1 Validation Rubrics'!N34) | Q32: =IF(N(O32)=0,"",ROUND(N(P32)/O32*100,2)) | R32: =IF('C1 Validation Rubrics'!O34="","",'C1 Validation Rubrics'!O34)
A33: 1.5 | B33: Programme Articulation Matrix | E33: #REF! | F33: #REF! | G33: #REF! | H33: =IF(COUNT(H34:H35)=0,"",SUM(H34:H35)) | I33: =IF(H33="","",ROUND(H33/E33*100,2)) | J33: =IF(I33="","",IF(I33>YT*100,"Y",IF(I33>=CT*100,"C",IF(I33>=WT*100,"W","D")))) | K33: =SUM(K34:K35) -> #VALUE! | L33: =SUM(L34:L35) -> #VALUE! | M33: =SUM(M34:M35) -> #VALUE! | N33: =SUM(N34:N35) -> #VALUE! | O33: =IF(COUNT(O34:O35)=0,"",SUM(O34:O35)) | P33: =IF(COUNT(P34:P35)=0,"",SUM(P34:P35)) | Q33: =IF(N(O33)=0,"",ROUND(N(P33)/O33*100,2))
A34: 1.5.a | B34: PAM derived from CAMs | C34: POs/PSOs with PAM value computed from CAMs / Total POs + PSOs | D34: % | E34: #REF! | F34: #REF! | G34: #REF! | H34: =IF(OR(G34="",F34="",F34=0),"",ROUND(E34*MIN(G34/F34,1),2)) -> #VALUE! | I34: =IF(H34="","",ROUND(H34/E34*100,2)) -> #VALUE! | J34: =IF(I34="","",IF(I34>YT*100,"Y",IF(I34>=CT*100,"C",IF(I34>=WT*100,"W","D")))) -> #VALUE! | K34: =IF($J34="Y",1,"") -> #VALUE! | L34: =IF($J34="C",1,"") -> #VALUE! | M34: =IF($J34="W",1,"") -> #VALUE! | N34: =IF($J34="D",1,"") -> #VALUE! | O34: =IF('C1 Validation Rubrics'!M36="","",'C1 Validation Rubrics'!M36) | P34: =IF('C1 Validation Rubrics'!N36="","",'C1 Validation Rubrics'!N36) | Q34: =IF(N(O34)=0,"",ROUND(N(P34)/O34*100,2)) | R34: =IF('C1 Validation Rubrics'!O36="","",'C1 Validation Rubrics'!O36)
A35: 1.5.b | B35: PO/PSO coverage | C35: POs/PSOs addressed by at least N courses / Total POs + PSOs | D35: % | E35: #REF! | F35: #REF! | G35: #REF! | H35: =IF(OR(G35="",F35="",F35=0),"",ROUND(E35*MIN(G35/F35,1),2)) -> #VALUE! | I35: =IF(H35="","",ROUND(H35/E35*100,2)) -> #VALUE! | J35: =IF(I35="","",IF(I35>YT*100,"Y",IF(I35>=CT*100,"C",IF(I35>=WT*100,"W","D")))) -> #VALUE! | K35: =IF($J35="Y",1,"") -> #VALUE! | L35: =IF($J35="C",1,"") -> #VALUE! | M35: =IF($J35="W",1,"") -> #VALUE! | N35: =IF($J35="D",1,"") -> #VALUE! | O35: =IF('C1 Validation Rubrics'!M37="","",'C1 Validation Rubrics'!M37) | P35: =IF('C1 Validation Rubrics'!N37="","",'C1 Validation Rubrics'!N37) | Q35: =IF(N(O35)=0,"",ROUND(N(P35)/O35*100,2)) | R35: =IF('C1 Validation Rubrics'!O37="","",'C1 Validation Rubrics'!O37)
A36: C1 | B36: CRITERION 1 TOTAL | E36: #REF! | F36: #REF! | G36: #REF! | H36: =IF(COUNT(H6,H15,H23,H27,H33)=0,"",N(H6)+N(H15)+N(H23)+N(H27)+N(H33)) | I36: =IF(H36="","",ROUND(H36/E36*100,2)) | J36: =IF(I36="","",IF(I36>YT*100,"Y",IF(I36>=CT*100,"C",IF(I36>=WT*100,"W","D")))) | K36: =N(K6)+N(K15)+N(K23)+N(K27)+N(K33) -> #VALUE! | L36: =N(L6)+N(L15)+N(L23)+N(L27)+N(L33) -> #VALUE! | M36: =N(M6)+N(M15)+N(M23)+N(M27)+N(M33) -> #VALUE! | N36: =N(N6)+N(N15)+N(N23)+N(N27)+N(N33) -> #VALUE! | O36: =IF(COUNT(O6,O15,O23,O27,O33)=0,"",N(O6)+N(O15)+N(O23)+N(O27)+N(O33)) | P36: =IF(COUNT(P6,P15,P23,P27,P33)=0,"",N(P6)+N(P15)+N(P23)+N(P27)+N(P33)) | Q36: =IF(N(O36)=0,"",ROUND(N(P36)/O36*100,2))
A37: C2 | B37: CRITERION 2 - OUTCOME-BASED TEACHING LEARNING
A38: 2.1 | B38: Quality of teaching-learning processes | E38: #REF! | F38: =IF('C2 Validation Rubrics'!R8="","",'C2 Validation Rubrics'!R8) | G38: =IF('C2 Validation Rubrics'!S8="","",'C2 Validation Rubrics'!S8) | H38: =IF(COUNT(H39:H43)=0,"",SUM(H39:H43)) | I38: =IF(H38="","",ROUND(H38/E38*100,2)) | J38: =IF(I38="","",IF(I38>YT*100,"Y",IF(I38>=CT*100,"C",IF(I38>=WT*100,"W","D")))) | K38: =SUM(K39:K43) -> #VALUE! | L38: =SUM(L39:L43) -> #VALUE! | M38: =SUM(M39:M43) -> #VALUE! | N38: =SUM(N39:N43) -> #VALUE! | O38: =IF(COUNT(O39:O43)=0,"",SUM(O39:O43)) | P38: =IF(COUNT(P39:P43)=0,"",SUM(P39:P43)) | Q38: =IF(N(O38)=0,"",ROUND(N(P38)/O38*100,2))
A39: 2.1.a | B39: Course files complete before semester start | C39: Courses with lesson plan + COs + CAM uploaded / Courses offered | D39: % | E39: #REF! | F39: =IF('C2 Validation Rubrics'!R9="","",'C2 Validation Rubrics'!R9) -> 3 | G39: =IF('C2 Validation Rubrics'!S9="","",'C2 Validation Rubrics'!S9) -> 2 | H39: =IF(OR(G39="",F39="",F39=0),"",ROUND(E39*MIN(G39/F39,1),2)) -> #VALUE! | I39: =IF(H39="","",ROUND(H39/E39*100,2)) -> #VALUE! | J39: =IF(I39="","",IF(I39>YT*100,"Y",IF(I39>=CT*100,"C",IF(I39>=WT*100,"W","D")))) -> #VALUE! | K39: =IF($J39="Y",1,"") -> #VALUE! | L39: =IF($J39="C",1,"") -> #VALUE! | M39: =IF($J39="W",1,"") -> #VALUE! | N39: =IF($J39="D",1,"") -> #VALUE! | O39: =IF('C2 Validation Rubrics'!M9="","",'C2 Validation Rubrics'!M9) | P39: =IF('C2 Validation Rubrics'!N9="","",'C2 Validation Rubrics'!N9) | Q39: =IF(N(O39)=0,"",ROUND(N(P39)/O39*100,2)) | R39: =IF('C2 Validation Rubrics'!O9="","",'C2 Validation Rubrics'!O9)
A40: 2.1.b | B40: Syllabus coverage as per lesson plan | C40: Topics covered / Topics planned to audit date | D40: % | E40: #REF! | F40: =IF('C2 Validation Rubrics'!R10="","",'C2 Validation Rubrics'!R10) | G40: =IF('C2 Validation Rubrics'!S10="","",'C2 Validation Rubrics'!S10) | H40: =IF(OR(G40="",F40="",F40=0),"",ROUND(E40*MIN(G40/F40,1),2)) | I40: =IF(H40="","",ROUND(H40/E40*100,2)) | J40: =IF(I40="","",IF(I40>YT*100,"Y",IF(I40>=CT*100,"C",IF(I40>=WT*100,"W","D")))) | K40: =IF($J40="Y",1,"") | L40: =IF($J40="C",1,"") | M40: =IF($J40="W",1,"") | N40: =IF($J40="D",1,"") | O40: =IF('C2 Validation Rubrics'!M10="","",'C2 Validation Rubrics'!M10) | P40: =IF('C2 Validation Rubrics'!N10="","",'C2 Validation Rubrics'!N10) | Q40: =IF(N(O40)=0,"",ROUND(N(P40)/O40*100,2)) | R40: =IF('C2 Validation Rubrics'!O10="","",'C2 Validation Rubrics'!O10)
A41: 2.1.c | B41: Classes conducted vs scheduled | C41: Hours conducted / Hours timetabled | D41: % | E41: #REF! | F41: =IF('C2 Validation Rubrics'!R11="","",'C2 Validation Rubrics'!R11) | G41: =IF('C2 Validation Rubrics'!S11="","",'C2 Validation Rubrics'!S11) | H41: =IF(OR(G41="",F41="",F41=0),"",ROUND(E41*MIN(G41/F41,1),2)) | I41: =IF(H41="","",ROUND(H41/E41*100,2)) | J41: =IF(I41="","",IF(I41>YT*100,"Y",IF(I41>=CT*100,"C",IF(I41>=WT*100,"W","D")))) | K41: =IF($J41="Y",1,"") | L41: =IF($J41="C",1,"") | M41: =IF($J41="W",1,"") | N41: =IF($J41="D",1,"") | O41: =IF('C2 Validation Rubrics'!M11="","",'C2 Validation Rubrics'!M11) | P41: =IF('C2 Validation Rubrics'!N11="","",'C2 Validation Rubrics'!N11) | Q41: =IF(N(O41)=0,"",ROUND(N(P41)/O41*100,2)) | R41: =IF('C2 Validation Rubrics'!O11="","",'C2 Validation Rubrics'!O11)
...

Sheet C1 Validation Rubrics
A1: CRITERION 1 - OUTCOME-BASED CURRICULUM - VALIDATION RUBRICS AND SAMPLE SIZES (physical audit)
A2: Sampling: check at least the Sample % of the population, but never fewer than the Minimum (check all items if the population is smaller). Sample % and Minimum are defaults - IQAC may change them.
A3: For % indicators: Validated value = Valid items / Items checked x 100. For count indicators: Validated value = number of claimed items found valid.
A4: Enter the Benchmark (col R) and Validated value (col S) here. Marks, Percentage and Grade (Y > 75, C 60-75, W 40-60, D < 40) are calculated automatically and flow to the C1 Quantitative and All Criteria tabs.
A5: Yellow/blue = input: Items checked, Valid items, Auditor remarks, Benchmark, Validated value (and Sample % / Minimum if IQAC changes them).
A7: Code | B7: Key aspect | C7: What the auditor verifies | D7: An item counts as valid only if | E7: Sampling unit | F7: Sample % | G7: Minimum sample | H7: How to sample | I7: Y (> 75%) | J7: C (60-75%) | K7: W (40-60%) | L7: D (< 40%) | M7: Items checked | N7: Valid items | O7: Auditor remarks | P7: Unit | Q7: Max marks | R7: Benchmark | S7: Validated value | T7: Marks obtained | U7: Percentage | V7: Grade | W7: Y | X7: C | Y7: W | Z7: D
A8: 1.1 | B8: Vision, Mission and PEOs | Q8: =SUM(Q9:Q16) -> 35 | R8: 30 | T8: =SUM(T9:T16) -> 0 | U8: =IF(COUNT(T9:T16)=0,"",ROUND(T8/Q8*100,2)) | V8: =IF(U8="","",IF(U8>YT*100,"Y",IF(U8>=CT*100,"C",IF(U8>=WT*100,"W","D")))) | W8: =SUM(W9:W16) -> 0 | X8: =SUM(X9:X16) -> 0 | Y8: =SUM(Y9:Y16) -> 0 | Z8: =SUM(Z9:Z16) -> 0
A9: 1.1.a | B9: Approval of Vision & Mission (1.1.1) | C9: Approval of Vision & Mission | D9: Signed minutes of IQAC, DAB and GB approving the current V&M | E9: Approvals (count) | F9: 1 | G9: 3 | H9: Check every required approval (IQAC, DAB, GB) | I9: All approvals with signed, dated minutes | J9: One approval with minutes unsigned or undated | K9: One approval missing | L9: Approvals not obtained or minutes absent | P9: % | Q9: 5 | T9: =IF(OR(S9="",R9="",R9=0),"",ROUND(Q9*MIN(S9/R9,1),2)) | U9: =IF(T9="","",ROUND(T9/Q9*100,2)) | V9: =IF(U9="","",IF(U9>YT*100,"Y",IF(U9>=CT*100,"C",IF(U9>=WT*100,"W","D")))) | W9: =IF($V9="Y",1,"") | X9: =IF($V9="C",1,"") | Y9: =IF($V9="W",1,"") | Z9: =IF($V9="D",1,"")
A10: 1.1.b | B10: Quality of PEOs (1.1.2) | C10: Quality of PEOs | D10: PEO is specific, measurable and describes graduates 3-5 years after graduation | E10: PEOs | F10: 1 | G10: 3 | H10: Check every PEO against the 3 criteria | I10: All PEOs meet all criteria | J10: Most PEOs meet criteria; wording minor gaps | K10: Several PEOs vague or not measurable | L10: PEOs not defined or copied from other programmes | P10: % | Q10: 5 | T10: =IF(OR(S10="",R10="",R10=0),"",ROUND(Q10*MIN(S10/R10,1),2)) | U10: =IF(T10="","",ROUND(T10/Q10*100,2)) | V10: =IF(U10="","",IF(U10>YT*100,"Y",IF(U10>=CT*100,"C",IF(U10>=WT*100,"W","D")))) | W10: =IF($V10="Y",1,"") | X10: =IF($V10="C",1,"") | Y10: =IF($V10="W",1,"") | Z10: =IF($V10="D",1,"")
A11: 1.1.c | B11: Stakeholder categories consulted (1.1.3) | C11: Stakeholder categories consulted | D11: Dated consultation record (minutes/survey) for the category | E11: Stakeholder categories | F11: 1 | G11: 6 | H11: Check all 6 categories (students, alumni, employers, parents, faculty, industry) | I11: All categories consulted with records | J11: One category missing | K11: Two or three categories missing | L11: Little or no documented consultation | P11: % | Q11: 5 | T11: =IF(OR(S11="",R11="",R11=0),"",ROUND(Q11*MIN(S11/R11,1),2)) | U11: =IF(T11="","",ROUND(T11/Q11*100,2)) | V11: =IF(U11="","",IF(U11>YT*100,"Y",IF(U11>=CT*100,"C",IF(U11>=WT*100,"W","D")))) | W11: =IF($V11="Y",1,"") | X11: =IF($V11="C",1,"") | Y11: =IF($V11="W",1,"") | Z11: =IF($V11="D",1,"")
A12: 1.1.d | B12: Stakeholder survey responses (1.1.3) | C12: Stakeholder survey responses | D12: Response traceable to a named respondent (form export with timestamp/email) | E12: Survey responses | F12: 0.1 | G12: 10 | H12: Random responses from raw survey export; call 2 respondents | I12: Responses meet target, all traceable | J12: Slightly below target; traceable | K12: Well below target or partly untraceable | L12: Responses not traceable or survey not done | P12: % | Q12: 5 | T12: =IF(OR(S12="",R12="",R12=0),"",ROUND(Q12*MIN(S12/R12,1),2)) | U12: =IF(T12="","",ROUND(T12/Q12*100,2)) | V12: =IF(U12="","",IF(U12>YT*100,"Y",IF(U12>=CT*100,"C",IF(U12>=WT*100,"W","D")))) | W12: =IF($V12="Y",1,"") | X12: =IF($V12="C",1,"") | Y12: =IF($V12="W",1,"") | Z12: =IF($V12="D",1,"")
A13: 1.1.e | B13: Dissemination points (1.1.4) | C13: Dissemination points | D13: V/M/PEOs physically displayed or published at the location | E13: Locations | F13: 1 | G13: 6 | H13: Walk-through of website, dept, labs, classrooms; open course files and handbook | I13: Displayed at all required points | J13: Missing at one point | K13: Missing at several points | L13: Not displayed | P13: % | Q13: 2 | T13: =IF(OR(S13="",R13="",R13=0),"",ROUND(Q13*MIN(S13/R13,1),2)) | U13: =IF(T13="","",ROUND(T13/Q13*100,2)) | V13: =IF(U13="","",IF(U13>YT*100,"Y",IF(U13>=CT*100,"C",IF(U13>=WT*100,"W","D")))) | W13: =IF($V13="Y",1,"") | X13: =IF($V13="C",1,"") | Y13: =IF($V13="W",1,"") | Z13: =IF($V13="D",1,"")
A14: 1.1.f | B14: Stakeholder awareness (1.1.4) | C14: Stakeholder awareness | D14: Student correctly states the gist of Vision, Mission and at least one PEO | E14: Students | F14: 0.05 | G14: 10 | H14: Interview random students across years during physical audit | I14: Most students aware | J14: Majority aware | K14: About half aware | L14: Few aware | P14: % | Q14: 3 | T14: =IF(OR(S14="",R14="",R14=0),"",ROUND(Q14*MIN(S14/R14,1),2)) | U14: =IF(T14="","",ROUND(T14/Q14*100,2)) | V14: =IF(U14="","",IF(U14>YT*100,"Y",IF(U14>=CT*100,"C",IF(U14>=WT*100,"W","D")))) | W14: =IF($V14="Y",1,"") | X14: =IF($V14="C",1,"") | Y14: =IF($V14="W",1,"") | Z14: =IF($V14="D",1,"")
A15: 1.1.g | B15: PEO-Mission mapping completeness (1.1.5) | C15: PEO-Mission mapping completeness | D15: Mapping cell filled with correlation level and written justification | E15: Mapping cells | F15: 0.25 | G15: 5 | H15: Random cells from PEO-Mission matrix | I15: All cells filled and justified | J15: Filled; justification thin in a few | K15: Several cells blank or unjustified | L15: Matrix absent | P15: % | Q15: 5 | T15: =IF(OR(S15="",R15="",R15=0),"",ROUND(Q15*MIN(S15/R15,1),2)) | U15: =IF(T15="","",ROUND(T15/Q15*100,2)) | V15: =IF(U15="","",IF(U15>YT*100,"Y",IF(U15>=CT*100,"C",IF(U15>=WT*100,"W","D")))) | W15: =IF($V15="Y",1,"") | X15: =IF($V15="C",1,"") | Y15: =IF($V15="W",1,"") | Z15: =IF($V15="D",1,"")
A16: 1.1.h | B16: PEO-Mission correlation strength (1.1.5) | C16: PEO-Mission correlation strength | D16: PEO has a strong (3) correlation that the justification supports | E16: PEOs | F16: 1 | G16: 3 | H16: Check every PEO | I16: All PEOs strongly mapped with sound justification | J16: Most strongly mapped | K16: Mostly weak correlations | L16: No strong correlations or unjustified | P16: % | Q16: 5 | T16: =IF(OR(S16="",R16="",R16=0),"",ROUND(Q16*MIN(S16/R16,1),2)) | U16: =IF(T16="","",ROUND(T16/Q16*100,2)) | V16: =IF(U16="","",IF(U16>YT*100,"Y",IF(U16>=CT*100,"C",IF(U16>=WT*100,"W","D")))) | W16: =IF($V16="Y",1,"") | X16: =IF($V16="C",1,"") | Y16: =IF($V16="W",1,"") | Z16: =IF($V16="D",1,"")
A17: 1.2 | B17: Curriculum structure and features | Q17: =SUM(Q18:Q24) -> 30 | T17: =SUM(T18:T24) -> 0 | U17: =IF(COUNT(T18:T24)=0,"",ROUND(T17/Q17*100,2)) | V17: =IF(U17="","",IF(U17>YT*100,"Y",IF(U17>=CT*100,"C",IF(U17>=WT*100,"W","D")))) | W17: =SUM(W18:W24) -> 0 | X17: =SUM(X18:X24) -> 0 | Y17: =SUM(Y18:Y24) -> 0 | Z17: =SUM(Z18:Z24) -> 0
A18: 1.2.a | B18: Curriculum feedback collected and analysed (1.2.1) | C18: Curriculum feedback analysed | D18: Feedback raw data + analysis report + BoS discussion for the category | E18: Stakeholder categories | F18: 1 | G18: 4 | H18: Check all 4 categories (students, alumni, employers, faculty) | I18: All categories analysed and discussed at BoS | J18: Analysed; BoS discussion partial | K18: Collected but not analysed | L18: Not collected | P18: % | Q18: 5 | T18: =IF(OR(S18="",R18="",R18=0),"",ROUND(Q18*MIN(S18/R18,1),2)) | U18: =IF(T18="","",ROUND(T18/Q18*100,2)) | V18: =IF(U18="","",IF(U18>YT*100,"Y",IF(U18>=CT*100,"C",IF(U18>=WT*100,"W","D")))) | W18: =IF($V18="Y",1,"") | X18: =IF($V18="C",1,"") | Y18: =IF($V18="W",1,"") | Z18: =IF($V18="D",1,"")
A19: 1.2.b | B19: Curriculum gaps addressed (1.2.1) | C19: Curriculum gaps addressed | D19: Gap has BoS revision or content-beyond-syllabus record with attendance | E19: Gaps | F19: 0.5 | G19: 3 | H19: Random gaps from the gap analysis register | I19: All sampled gaps closed with proof | J19: Most closed | K19: About half closed | L19: Few or none closed | P19: % | Q19: 5 | T19: =IF(OR(S19="",R19="",R19=0),"",ROUND(Q19*MIN(S19/R19,1),2)) | U19: =IF(T19="","",ROUND(T19/Q19*100,2)) | V19: =IF(U19="","",IF(U19>YT*100,"Y",IF(U19>=CT*100,"C",IF(U19>=WT*100,"W","D")))) | W19: =IF($V19="Y",1,"") | X19: =IF($V19="C",1,"") | Y19: =IF($V19="W",1,"") | Z19: =IF($V19="D",1,"")
A20: 1.2.c | B20: Complete syllabi (1.2.2) | C20: Complete syllabi | D20: Syllabus has COs, unit content, hours, text and reference books | E20: Courses | F20: 0.2 | G20: 5 | H20: Random courses across semesters incl. electives and labs | I20: All complete | J20: Minor elements missing in a few | K20: Several incomplete | L20: Syllabi largely incomplete | P20: % | Q20: 5 | T20: =IF(OR(S20="",R20="",R20=0),"",ROUND(Q20*MIN(S20/R20,1),2)) | U20: =IF(T20="","",ROUND(T20/Q20*100,2)) | V20: =IF(U20="","",IF(U20>YT*100,"Y",IF(U20>=CT*100,"C",IF(U20>=WT*100,"W","D")))) | W20: =IF($V20="Y",1,"") | X20: =IF($V20="C",1,"") | Y20: =IF($V20="W",1,"") | Z20: =IF($V20="D",1,"")
A21: 1.2.d | B21: Credit compliance (1.2.2) | C21: Credit compliance | D21: Semester credits within university/AICTE norm as per approved scheme | E21: Semesters | F21: 1 | G21: 8 | H21: Check every semester in approved curriculum | I21: All semesters compliant | J21: One semester marginally off | K21: Several semesters off | L21: Scheme not compliant | P21: % | Q21: 5 | T21: =IF(OR(S21="",R21="",R21=0),"",ROUND(Q21*MIN(S21/R21,1),2)) | U21: =IF(T21="","",ROUND(T21/Q21*100,2)) | V21: =IF(U21="","",IF(U21>YT*100,"Y",IF(U21>=CT*100,"C",IF(U21>=WT*100,"W","D")))) | W21: =IF($V21="Y",1,"") | X21: =IF($V21="C",1,"") | Y21: =IF($V21="W",1,"") | Z21: =IF($V21="D",1,"")
A22: 1.2.e | B22: Curriculum components within AICTE range (1.2.3) | C22: Curriculum components in AICTE range | D22: Category credits within AICTE range in approved scheme | E22: Categories | F22: 1 | G22: 7 | H22: Check all 7 categories (BS, ES, HSS, PC, PE, OE, Project) | I22: All 7 within range | J22: 6 within range | K22: 4-5 within range | L22: Fewer than 4 within range | P22: % | Q22: 5 | T22: =IF(OR(S22="",R22="",R22=0),"",ROUND(Q22*MIN(S22/R22,1),2)) | U22: =IF(T22="","",ROUND(T22/Q22*100,2)) | V22: =IF(U22="","",IF(U22>YT*100,"Y",IF(U22>=CT*100,"C",IF(U22>=WT*100,"W","D")))) | W22: =IF($V22="Y",1,"") | X22: =IF($V22="C",1,"") | Y22: =IF($V22="W",1,"") | Z22: =IF($V22="D",1,"")
A23: 1.2.f | B23: Interdisciplinary / honours / minor options (1.2.4) | C23: Interdisciplinary / honours / minor options | D23: Option approved by BoS/AC with student enrolment record | E23: Options (count) | F23: 1 | G23: 3 | H23: Verify every claimed option | I23: Meets benchmark, enrolments verified | J23: Slightly below benchmark | K23: Well below benchmark | L23: None offered | P23: No. | Q23: 2 | T23: =IF(OR(S23="",R23="",R23=0),"",ROUND(Q23*MIN(S23/R23,1),2)) | U23: =IF(T23="","",ROUND(T23/Q23*100,2)) | V23: =IF(U23="","",IF(U23>YT*100,"Y",IF(U23>=CT*100,"C",IF(U23>=WT*100,"W","D")))) | W23: =IF($V23="Y",1,"") | X23: =IF($V23="C",1,"") | Y23: =IF($V23="W",1,"") | Z23: =IF($V23="D",1,"")
A24: 1.2.g | B24: Academic Bank of Credits registration (1.2.4) | C24: ABC registration | D24: ABC ID verifiable on the ABC/DigiLocker list for the student | E24: Students | F24: 0.1 | G24: 10 | H24: Random students from roll list; match with ABC portal export | I24: All sampled students registered | J24: Most registered | K24: About half registered | L24: Few registered | P24: % | Q24: 3 | T24: =IF(OR(S24="",R24="",R24=0),"",ROUND(Q24*MIN(S24/R24,1),2)) | U24: =IF(T24="","",ROUND(T24/Q24*100,2)) | V24: =IF(U24="","",IF(U24>YT*100,"Y",IF(U24>=CT*100,"C",IF(U24>=WT*100,"W","D")))) | W24: =IF($V24="Y",1,"") | X24: =IF($V24="C",1,"") | Y24: =IF($V24="W",1,"") | Z24: =IF($V24="D",1,"")
A25: 1.3 | B25: Mapping of POs and PSOs | Q25: =SUM(Q26:Q28) -> 20 | T25: =SUM(T26:T28) -> 0 | U25: =IF(COUNT(T26:T28)=0,"",ROUND(T25/Q25*100,2)) | V25: =IF(U25="","",IF(U25>YT*100,"Y",IF(U25>=CT*100,"C",IF(U25>=WT*100,"W","D")))) | W25: =SUM(W26:W28) -> 0 | X25: =SUM(X26:X28) -> 0 | Y25: =SUM(Y26:Y28) -> 0 | Z25: =SUM(Z26:Z28) -> 0
A26: 1.3.a | B26: PSOs defined and approved (1.3.1) | C26: PSOs defined and approved | D26: PSO approved in signed BoS/DAB minutes | E26: PSOs | F26: 1 | G26: 2 | H26: Check every PSO | I26: All PSOs approved and programme-specific | J26: Approved; wording generic | K26: Partly approved | L26: Not approved | P26: % | Q26: 5 | T26: =IF(OR(S26="",R26="",R26=0),"",ROUND(Q26*MIN(S26/R26,1),2)) | U26: =IF(T26="","",ROUND(T26/Q26*100,2)) | V26: =IF(U26="","",IF(U26>YT*100,"Y",IF(U26>=CT*100,"C",IF(U26>=WT*100,"W","D")))) | W26: =IF($V26="Y",1,"") | X26: =IF($V26="C",1,"") | Y26: =IF($V26="W",1,"") | Z26: =IF($V26="D",1,"")
A27: 1.3.b | B27: Courses mapped to POs/PSOs (1.3.2) | C27: Courses mapped to POs/PSOs | D27: Course has CO-PO/PSO mapping table in course file | E27: Courses | F27: 0.2 | G27: 5 | H27: Random courses across all semesters | I27: All mapped | J27: Most mapped | K27: About half mapped | L27: Few or none | P27: % | Q27: 8 | T27: =IF(OR(S27="",R27="",R27=0),"",ROUND(Q27*MIN(S27/R27,1),2)) | U27: =IF(T27="","",ROUND(T27/Q27*100,2)) | V27: =IF(U27="","",IF(U27>YT*100,"Y",IF(U27>=CT*100,"C",IF(U27>=WT*100,"W","D")))) | W27: =IF($V27="Y",1,"") | X27: =IF($V27="C",1,"") | Y27: =IF($V27="W",1,"") | Z27: =IF($V27="D",1,"")
A28: 1.3.c | B28: Justified mappings (1.3.2) | C28: Justified mappings | D28: Each correlation level in the mapping has written justification | E28: Mapped courses | F28: 0.2 | G28: 5 | H28: Same courses as 1.3.b | I28: All justified and consistent | J28: Most justified | K28: Justification weak or generic | L28: No justification | P28: % | Q28: 7 | T28: =IF(OR(S28="",R28="",R28=0),"",ROUND(Q28*MIN(S28/R28,1),2)) | U28: =IF(T28="","",ROUND(T28/Q28*100,2)) | V28: =IF(U28="","",IF(U28>YT*100,"Y",IF(U28>=CT*100,"C",IF(U28>=WT*100,"W","D")))) | W28: =IF($V28="Y",1,"") | X28: =IF($V28="C",1,"") | Y28: =IF($V28="W",1,"") | Z28: =IF($V28="D",1,"")
A29: 1.4 | B29: Course Outcomes and Course Articulation Matrix | Q29: =SUM(Q30:Q34) -> 30 | T29: =SUM(T30:T34) -> 0 | U29: =IF(COUNT(T30:T34)=0,"",ROUND(T29/Q29*100,2)) | V29: =IF(U29="","",IF(U29>YT*100,"Y",IF(U29>=CT*100,"C",IF(U29>=WT*100,"W","D")))) | W29: =SUM(W30:W34) -> 0 | X29: =SUM(X30:X34) -> 0 | Y29: =SUM(Y30:Y34) -> 0 | Z29: =SUM(Z30:Z34) -> 0
A30: 1.4.a | B30: Courses with COs defined (1.4.1) | C30: Courses with COs defined | D30: Course file lists 4-6 COs approved by course committee | E30: Courses | F30: 0.2 | G30: 5 | H30: Random courses offered in the period | I30: All courses have COs | J30: Most have COs | K30: About half | L30: Few or none | P30: % | Q30: 5 | T30: =IF(OR(S30="",R30="",R30=0),"",ROUND(Q30*MIN(S30/R30,1),2)) | U30: =IF(T30="","",ROUND(T30/Q30*100,2)) | V30: =IF(U30="","",IF(U30>YT*100,"Y",IF(U30>=CT*100,"C",IF(U30>=WT*100,"W","D")))) | W30: =IF($V30="Y",1,"") | X30: =IF($V30="C",1,"") | Y30: =IF($V30="W",1,"") | Z30: =IF($V30="D",1,"")
A31: 1.4.b | B31: Measurable COs (1.4.1) | C31: Measurable COs | D31: CO starts with action verb and states Bloom level | E31: COs | F31: 0.1 | G31: 15 | H31: Random COs from sampled courses | I31: All measurable | J31: Most measurable | K31: About half | L31: Mostly vague | P31: % | Q31: 5 | T31: =IF(OR(S31="",R31="",R31=0),"",ROUND(Q31*MIN(S31/R31,1),2)) | U31: =IF(T31="","",ROUND(T31/Q31*100,2)) | V31: =IF(U31="","",IF(U31>YT*100,"Y",IF(U31>=CT*100,"C",IF(U31>=WT*100,"W","D")))) | W31: =IF($V31="Y",1,"") | X31: =IF($V31="C",1,"") | Y31: =IF($V31="W",1,"") | Z31: =IF($V31="D",1,"")
A32: 1.4.c | B32: Higher-order COs (1.4.1) | C32: Higher-order COs | D32: Course has at least one CO at Apply level or above, assessed in CA | E32: Courses | F32: 0.2 | G32: 5 | H32: Same courses as 1.4.a | I32: All courses have higher-order COs | J32: Most | K32: About half | L32: Few or none | P32: % | Q32: 5 | T32: =IF(OR(S32="",R32="",R32=0),"",ROUND(Q32*MIN(S32/R32,1),2)) | U32: =IF(T32="","",ROUND(T32/Q32*100,2)) | V32: =IF(U32="","",IF(U32>YT*100,"Y",IF(U32>=CT*100,"C",IF(U32>=WT*100,"W","D")))) | W32: =IF($V32="Y",1,"") | X32: =IF($V32="C",1,"") | Y32: =IF($V32="W",1,"") | Z32: =IF($V32="D",1,"")
A33: 1.4.d | B33: Course Articulation Matrix prepared (1.4.2) | C33: Course Articulation Matrix prepared | D33: CAM present in course file and approved | E33: Courses | F33: 0.2 | G33: 5 | H33: Random courses | I33: All have CAM | J33: Most have CAM | K33: About half | L33: Few or none | P33: % | Q33: 8 | T33: =IF(OR(S33="",R33="",R33=0),"",ROUND(Q33*MIN(S33/R33,1),2)) | U33: =IF(T33="","",ROUND(T33/Q33*100,2)) | V33: =IF(U33="","",IF(U33>YT*100,"Y",IF(U33>=CT*100,"C",IF(U33>=WT*100,"W","D")))) | W33: =IF($V33="Y",1,"") | X33: =IF($V33="C",1,"") | Y33: =IF($V33="W",1,"") | Z33: =IF($V33="D",1,"")
A34: 1.4.e | B34: CAM correlations justified (1.4.2) | C34: CAM correlations justified | D34: Every correlation in the CAM has justification | E34: CAMs | F34: 0.2 | G34: 5 | H34: Random CAMs from 1.4.d sample | I34: All justified | J34: Most justified | K34: Partly justified | L34: Not justified | P34: % | Q34: 7 | T34: =IF(OR(S34="",R34="",R34=0),"",ROUND(Q34*MIN(S34/R34,1),2)) | U34: =IF(T34="","",ROUND(T34/Q34*100,2)) | V34: =IF(U34="","",IF(U34>YT*100,"Y",IF(U34>=CT*100,"C",IF(U34>=WT*100,"W","D")))) | W34: =IF($V34="Y",1,"") | X34: =IF($V34="C",1,"") | Y34: =IF($V34="W",1,"") | Z34: =IF($V34="D",1,"")
A35: 1.5 | B35: Programme Articulation Matrix | Q35: =SUM(Q36:Q37) -> 5 | T35: =SUM(T36:T37) -> 0 | U35: =IF(COUNT(T36:T37)=0,"",ROUND(T35/Q35*100,2)) | V35: =IF(U35="","",IF(U35>YT*100,"Y",IF(U35>=CT*100,"C",IF(U35>=WT*100,"W","D")))) | W35: =SUM(W36:W37) -> 0 | X35: =SUM(X36:X37) -> 0 | Y35: =SUM(Y36:Y37) -> 0 | Z35: =SUM(Z36:Z37) -> 0
A36: 1.5.a | B36: PAM derived from CAMs | C36: PAM derived from CAMs | D36: PAM value recomputed by auditor matches the sheet (within 0.1) | E36: POs/PSOs | F36: 0.5 | G36: 5 | H36: Recompute PAM for random POs/PSOs from CAMs | I36: All recomputed values match | J36: Minor deviations | K36: Several mismatches | L36: PAM not derived from CAMs | P36: % | Q36: 3 | T36: =IF(OR(S36="",R36="",R36=0),"",ROUND(Q36*MIN(S36/R36,1),2)) | U36: =IF(T36="","",ROUND(T36/Q36*100,2)) | V36: =IF(U36="","",IF(U36>YT*100,"Y",IF(U36>=CT*100,"C",IF(U36>=WT*100,"W","D")))) | W36: =IF($V36="Y",1,"") | X36: =IF($V36="C",1,"") | Y36: =IF($V36="W",1,"") | Z36: =IF($V36="D",1,"")
A37: 1.5.b | B37: PO/PSO coverage | C37: PO/PSO coverage | D37: PO/PSO addressed by at least N courses in PAM | E37: POs/PSOs | F37: 1 | G37: 12 | H37: Check all POs and PSOs in PAM | I37: All POs/PSOs adequately covered | J37: One or two thinly covered | K37: Several thinly covered | L37: Many POs/PSOs uncovered | P37: % | Q37: 2 | T37: =IF(OR(S37="",R37="",R37=0),"",ROUND(Q37*MIN(S37/R37,1),2)) | U37: =IF(T37="","",ROUND(T37/Q37*100,2)) | V37: =IF(U37="","",IF(U37>YT*100,"Y",IF(U37>=CT*100,"C",IF(U37>=WT*100,"W","D")))) | W37: =IF($V37="Y",1,"") | X37: =IF($V37="C",1,"") | Y37: =IF($V37="W",1,"") | Z37: =IF($V37="D",1,"")
A38: C1 | B38: CRITERION 1 TOTAL | Q38: =Q8+Q17+Q25+Q29+Q35 -> 120 | T38: =T8+T17+T25+T29+T35 -> 0 | U38: =IF(T38=0,"",ROUND(T38/Q38*100,2)) | V38: =IF(U38="","",IF(U38>YT*100,"Y",IF(U38>=CT*100,"C",IF(U38>=WT*100,"W","D")))) | W38: =W8+W17+W25+W29+W35 -> 0 | X38: =X8+X17+X25+X29+X35 -> 0 | Y38: =Y8+Y17+Y25+Y29+Y35 -> 0 | Z38: =Z8+Z17+Z25+Z29+Z35 -> 0

Sheet C2 Validation Rubrics
A1: CRITERION 2 - VALIDATION RUBRICS AND SAMPLE SIZES (physical audit)
A2: Sampling: check at least the Sample % of the population, but never fewer than the Minimum (check all items if the population is smaller). Sample % and Minimum are defaults - IQAC may change them.
A3: For % indicators: Validated value = Valid items / Items checked x 100. For count indicators: Validated value = number of claimed items found valid.
A4: Enter the Benchmark (col R) and Validated value (col S) here. Marks, Percentage and Grade (Y > 75, C 60-75, W 40-60, D < 40) are calculated automatically and flow to the C2 Quantitative and All Criteria tabs.
A5: Yellow/blue = input: Items checked, Valid items, Auditor remarks, Benchmark, Validated value (and Sample % / Minimum if IQAC changes them).
A7: Code | B7: Key aspect | C7: What the auditor verifies | D7: An item counts as valid only if | E7: Sampling unit | F7: Sample % | G7: Minimum sample | H7: How to sample | I7: Y (> 75%) | J7: C (60-75%) | K7: W (40-60%) | L7: D (< 40%) | M7: Items checked | N7: Valid items | O7: Auditor remarks | P7: Unit | Q7: Max marks | R7: Benchmark | S7: Validated value | T7: Marks obtained | U7: Percentage | V7: Grade | W7: Y | X7: C | Y7: W | Z7: D
A8: 2.1 | B8: Quality of teaching-learning processes | Q8: =SUM(Q9:Q13) -> 20 | T8: =SUM(T9:T13) -> 2.67 | U8: =IF(COUNT(T9:T13)=0,"",ROUND(T8/Q8*100,2)) -> 13.35 | V8: =IF(U8="","",IF(U8>YT*100,"Y",IF(U8>=CT*100,"C",IF(U8>=WT*100,"W","D")))) -> D | W8: =SUM(W9:W13) -> 0 | X8: =SUM(X9:X13) -> 1 | Y8: =SUM(Y9:Y13) -> 0 | Z8: =SUM(Z9:Z13) -> 0
A9: 2.1.a | B9: Course files complete before semester start | C9: Completeness of course files before semester start | D9: File has lesson plan, COs, CAM, timetable and dated upload before semester start | E9: Courses | F9: 0.25 | G9: 3 | H9: Random draw across all years; include at least 1 lab course | I9: All components present, dated before start, signed by HoD | J9: Minor component missing in a few files (e.g. CAM unsigned) | K9: Several files missing CAM or lesson plan; late uploads | L9: Files absent or prepared after semester start | P9: % | Q9: 4 | R9: 3 | S9: 2 | T9: =IF(OR(S9="",R9="",R9=0),"",ROUND(Q9*MIN(S9/R9,1),2)) -> 2.67 | U9: =IF(T9="","",ROUND(T9/Q9*100,2)) -> 66.75 | V9: =IF(U9="","",IF(U9>YT*100,"Y",IF(U9>=CT*100,"C",IF(U9>=WT*100,"W","D")))) -> C | W9: =IF($V9="Y",1,"") | X9: =IF($V9="C",1,"") -> 1 | Y9: =IF($V9="W",1,"") | Z9: =IF($V9="D",1,"")
A10: 2.1.b | B10: Syllabus coverage as per lesson plan | C10: Syllabus coverage vs lesson plan | D10: Topics in log book match lesson plan to audit date (lag <= 1 week) | E10: Courses | F10: 0.25 | G10: 3 | H10: Same courses as 2.1.a; compare log book, attendance and lesson plan | I10: On schedule or ahead; log book tallies with attendance | J10: Lag 1-2 weeks with documented recovery plan | K10: Lag 2-3 weeks; no recovery plan | L10: Lag beyond 3 weeks or log book not maintained | P10: % | Q10: 4 | T10: =IF(OR(S10="",R10="",R10=0),"",ROUND(Q10*MIN(S10/R10,1),2)) | U10: =IF(T10="","",ROUND(T10/Q10*100,2)) | V10: =IF(U10="","",IF(U10>YT*100,"Y",IF(U10>=CT*100,"C",IF(U10>=WT*100,"W","D")))) | W10: =IF($V10="Y",1,"") | X10: =IF($V10="C",1,"") | Y10: =IF($V10="W",1,"") | Z10: =IF($V10="D",1,"")
A11: 2.1.c | B11: Classes conducted vs scheduled | C11: Classes conducted vs timetabled | D11: Hours in attendance register equal timetabled hours (missed hours compensated) | E11: Course-weeks | F11: 0.1 | G11: 4 | H11: Pick 1 random week for each sampled course | I11: All scheduled hours held or compensated | J11: Up to 10% hours missed, partly compensated | K11: 10-25% hours missed | L11: Over 25% hours missed or registers incomplete | P11: % | Q11: 4 | T11: =IF(OR(S11="",R11="",R11=0),"",ROUND(Q11*MIN(S11/R11,1),2)) | U11: =IF(T11="","",ROUND(T11/Q11*100,2)) | V11: =IF(U11="","",IF(U11>YT*100,"Y",IF(U11>=CT*100,"C",IF(U11>=WT*100,"W","D")))) | W11: =IF($V11="Y",1,"") | X11: =IF($V11="C",1,"") | Y11: =IF($V11="W",1,"") | Z11: =IF($V11="D",1,"")
